Workbook

Sheet OIK104corrected
A1: RECIPE CODE | B1: RECIPENAME | C1: NEW RECIPE NAME | D1: INGREDIENT CODE | E1: IME CODE | F1: INGREDIENT | G1: NEW INGREDIENT | H1: GRAMS / TMX | I1: CATEGORY | J1: KG / TMX | K1: Cost per Kg | L1: costcost | M1: OIK104 MENU | N1: Ingredient (from Ingredient Name) | O1: Kg per Recipe | P1: Cost per Recipe | Q1: costcosrecipe | R1: OIK104 MENU copy | S1: CATEGORY_ | T1: RESTAURANT (from OIK104 MENU) | U1: OIK512 MENU INGREDIENTS_ | V1: RESTAURANT (from OIK512 MENU_) (from OIK512 MENU INGREDIENTS_) | W1: Column1 | X1: Column2 | Y1: Column3 | Z1: Column4 | AA1: Column5 | AB1: ΣΧΟΛΙΑ
A2: U6153 | B2: 4 ΕΠΟΧΕΣ | D2: =VLOOKUP(F:F,Sheet1!A:B,2,FALSE) -> U3066 | F2: ΕΝΤΑΜ | H2: 90 | I2: ΠΙΤΣΑ | J2: 1000 | K2: 7.2 | L2: 7.2 | N2: ΕΝΤΑΜ | O2: 0.09 | P2: 0.65 | Q2: 0.65 | S2: ΠΙΤΣΑ | U2: 4 ΕΠΟΧΕΣ | V2: OIK512
A3: U6153 | B3: 4 ΕΠΟΧΕΣ | D3: =VLOOKUP(F:F,Sheet1!A:B,2,FALSE) -> U3075 | F3: ΖΥΜΗ ΠΙΤΣΑΣ 54 ΜΕΡΙΔΕΣ | H3: 1 | I3: ΠΙΤΣΑ | J3: 1 | L3: 0.45 | N3: ΖΥΜΗ ΠΙΤΣΑΣ 54 ΜΕΡΙΔΕΣ | O3: 1 | P3: 0 | Q3: 0.45 | S3: ΠΙΤΣΑ | U3: 4 ΕΠΟΧΕΣ | V3: OIK512
A4: U6153 | B4: 4 ΕΠΟΧΕΣ | D4: =VLOOKUP(F:F,Sheet1!A:B,2,FALSE) -> U3143 | F4: ΜΑΝΙΤΑΡΙΑ | H4: 40 | I4: ΠΙΤΣΑ | J4: 1000 | K4: 2.14 | L4: 2.14 | N4: ΜΑΝΙΤΑΡΙΑ | O4: 0.04 | P4: 0.09 | Q4: 0.09 | S4: ΠΙΤΣΑ | U4: 4 ΕΠΟΧΕΣ | V4: OIK512
A5: U6153 | B5: 4 ΕΠΟΧΕΣ | D5: =VLOOKUP(F:F,Sheet1!A:B,2,FALSE) -> U3164 | F5: ΜΟΤΣΑΡΕΛΑ | H5: 90 | I5: ΠΙΤΣΑ | J5: 1000 | K5: 6.74 | L5: 6.74 | N5: ΜΟΤΣΑΡΕΛΑ | O5: 0.09 | P5: 0.61 | Q5: 0.61 | S5: ΠΙΤΣΑ | U5: 4 ΕΠΟΧΕΣ | V5: OIK512
A6: U6153 | B6: 4 ΕΠΟΧΕΣ | D6: =VLOOKUP(F:F,Sheet1!A:B,2,FALSE) -> U3170 | F6: ΜΠΕΙΚΟΝ ΚΑΠΝΙΣΤΟ | H6: 40 | I6: ΠΙΤΣΑ | J6: 1000 | K6: 5.31 | L6: 5.31 | N6: ΜΠΕΙΚΟΝ ΚΑΠΝΙΣΤΟ | O6: 0.04 | P6: 0.21 | Q6: 0.21 | S6: ΠΙΤΣΑ | U6: 4 ΕΠΟΧΕΣ | V6: OIK512
A7: U6153 | B7: 4 ΕΠΟΧΕΣ | D7: =VLOOKUP(F:F,Sheet1!A:B,2,FALSE) -> U3207 | F7: ΠΕΠΕΡΟΝΙ | H7: 30 | I7: ΠΙΤΣΑ | J7: 1000 | K7: 4.18 | L7: 4.18 | N7: ΠΕΠΕΡΟΝΙ | O7: 0.03 | P7: 0.13 | Q7: 0.13 | S7: ΠΙΤΣΑ | U7: 4 ΕΠΟΧΕΣ | V7: OIK512
A8: U6153 | B8: 4 ΕΠΟΧΕΣ | D8: =VLOOKUP(F:F,Sheet1!A:B,2,FALSE) -> U3208 | F8: ΠΙΚ ΝΙΚ | H8: 40 | I8: ΠΙΤΣΑ | J8: 1000 | K8: 3.12 | L8: 3.12 | N8: ΠΙΚ ΝΙΚ | O8: 0.04 | P8: 0.12 | Q8: 0.12 | S8: ΠΙΤΣΑ | U8: 4 ΕΠΟΧΕΣ | V8: OIK512
A9: U6153 | B9: 4 ΕΠΟΧΕΣ | D9: =VLOOKUP(F:F,Sheet1!A:B,2,FALSE) -> U3252 | F9: ΣΑΛΤΣΑ ΠΙΤΣΑΣ | H9: 80 | I9: ΠΙΤΣΑ | J9: 1000 | L9: 11.7 | N9: ΣΑΛΤΣΑ ΠΙΤΣΑΣ | O9: 0.08 | P9: 0 | Q9: 0.94 | S9: ΠΙΤΣΑ | U9: 4 ΕΠΟΧΕΣ | V9: OIK512
A10: U6392 | B10: AFFOGATO | D10: =VLOOKUP(F:F,Sheet1!A:B,2,FALSE) -> #N/A | F10: RISTRETTO | H10: 24 | I10: ΕΠΙΔΟΡΠΙΑ | J10: 1000 | AB10: ΟΙΚ104
A11: U6392 | B11: AFFOGATO | D11: =VLOOKUP(F:F,Sheet1!A:B,2,FALSE) -> #N/A | F11: ΠΑΓΩΤΟ | H11: 100 | I11: ΕΠΙΔΟΡΠΙΑ | J11: 1000 | AB11: ΟΙΚ104
A12: U6298 | B12: MEDALLION | D12: =VLOOKUP(F:F,Sheet1!A:B,2,FALSE) -> #N/A | F12: ΚΑΤΣΙΚΙΣΙΟ ΤΥΡΙ | H12: 50 | I12: ΤΥΡΙΑ | J12: 1000 | K12: 17.5 | L12: 17.5 | N12: MEDALLION | O12: 0.05 | P12: 0.88 | Q12: 0.88 | S12: ΤΥΡΙΑ | AB12: Η ΒΑΣΩ ΕΙΠΕ ΣΤΟ MEDALLION ΧΡΗΣΙΜΟΠΟΙΟΥΝ ΚΑΤΣΙΚΙΣΙΟ ΤΥΡΙ
A13: U6294 | B13: REZZANO | C13: REZZANA TOSSIZZA | D13: =VLOOKUP(F:F,Sheet1!A:B,2,FALSE) -> U3010 | F13: REZZANO | H13: 50 | I13: ΤΥΡΙΑ | J13: 1000 | K13: 20.19 | L13: 20.19 | N13: REZZANO | O13: 0.05 | P13: 1.01 | Q13: 1.01 | S13: ΤΥΡΙΑ
A14: U6296 | B14: TΣΑΛΑΦΟΥΤΙ | C14: TSALAFOUTI | D14: =VLOOKUP(F:F,Sheet1!A:B,2,FALSE) -> U3291 | F14: ΤΣΑΛΑΦΟΥΤΙ | H14: 50 | I14: ΤΥΡΙΑ | J14: 1000 | K14: 5.5 | L14: 5.5 | N14: ΤΣΑΛΑΦΟΥΤΙ | O14: 0.05 | P14: 0.28 | Q14: 0.28 | S14: ΤΥΡΙΑ
A15: U6315 | B15: VEGAN CHEESECAKE 16ΜΕΡΙΔΕΣ (1600GR) | C15: RASPBERRY VEGAN CHEESCAKE 16ΜΕΡΙΔΕΣ (1600GR) | D15: =VLOOKUP(F:F,Sheet1!A:B,2,FALSE) -> U3004 | F15: CHIA ΣΠΟΡΟΙ | H15: 50 | I15: ΕΠΙΔΟΡΠΙΑ | J15: 1000 | K15: 3.89 | L15: 3.89 | N15: CHIA ΣΠΟΡΟΙ | O15: 0.05 | P15: 0.19 | Q15: 0.19 | S15: ΕΠΙΔΟΡΠΙΑ
A16: U6315 | B16: VEGAN CHEESECAKE 16ΜΕΡΙΔΕΣ (1600GR) | C16: RASPBERRY VEGAN CHEESCAKE 16ΜΕΡΙΔΕΣ (1600GR) | D16: =VLOOKUP(F:F,Sheet1!A:B,2,FALSE) -> U3022 | F16: ΑΜΥΓΔΑΛΟΨΥΧΑ 1kg | H16: 200 | I16: ΕΠΙΔΟΡΠΙΑ | J16: 1000 | K16: 8.75 | L16: 8.75 | N16: ΑΜΥΓΔΑΛΟΨΥΧΑ 1kg | O16: 0.2 | P16: 1.75 | Q16: 1.75 | S16: ΕΠΙΔΟΡΠΙΑ
A17: U6315 | B17: VEGAN CHEESECAKE 16ΜΕΡΙΔΕΣ (1600GR) | C17: RASPBERRY VEGAN CHEESCAKE 16ΜΕΡΙΔΕΣ (1600GR) | D17: =VLOOKUP(F:F,Sheet1!A:B,2,FALSE) -> U3034 | F17: ΒΑΝΙΛΙΑ | H17: 1 | I17: ΕΠΙΔΟΡΠΙΑ | J17: 1000 | K17: 34.07 | L17: 34.07 | N17: ΒΑΝΙΛΙΑ | O17: 0 | P17: 0.03 | Q17: 0.03 | S17: ΕΠΙΔΟΡΠΙΑ
A18: U6315 | B18: VEGAN CHEESECAKE 16ΜΕΡΙΔΕΣ (1600GR) | C18: RASPBERRY VEGAN CHEESCAKE 16ΜΕΡΙΔΕΣ (1600GR) | D18: =VLOOKUP(F:F,Sheet1!A:B,2,FALSE) -> U3036 | F18: ΒΑΤΟΜΟΥΡΟ ΚΟΚΚΙΝΟ | H18: 200 | I18: ΕΠΙΔΟΡΠΙΑ | J18: 1000 | K18: 4.65 | L18: 4.65 | N18: ΒΑΤΟΜΟΥΡΟ ΚΟΚΚΙΝΟ | O18: 0.2 | P18: 0.93 | Q18: 0.93 | S18: ΕΠΙΔΟΡΠΙΑ
A19: U6315 | B19: VEGAN CHEESECAKE 16ΜΕΡΙΔΕΣ (1600GR) | C19: RASPBERRY VEGAN CHEESCAKE 16ΜΕΡΙΔΕΣ (1600GR) | D19: =VLOOKUP(F:F,Sheet1!A:B,2,FALSE) -> U3047 | F19: ΓΑΛΑ ΚΑΡΥΔΑΣ | H19: 180 | I19: ΕΠΙΔΟΡΠΙΑ | J19: 1000 | K19: 2.08 | L19: 2.08 | N19: ΓΑΛΑ ΚΑΡΥΔΑΣ | O19: 0.18 | P19: 0.37 | Q19: 0.37 | S19: ΕΠΙΔΟΡΠΙΑ
A20: U6315 | B20: VEGAN CHEESECAKE 16ΜΕΡΙΔΕΣ (1600GR) | C20: RASPBERRY VEGAN CHEESCAKE 16ΜΕΡΙΔΕΣ (1600GR) | D20: =VLOOKUP(F:F,Sheet1!A:B,2,FALSE) -> U3091 | F20: ΚΑΣΙΟΥΣ ΩΜΑ | H20: 335 | I20: ΕΠΙΔΟΡΠΙΑ | J20: 1000 | K20: 7.65 | L20: 7.65 | N20: ΚΑΣΙΟΥΣ ΩΜΑ | O20: 0.34 | P20: 2.56 | Q20: 2.56 | S20: ΕΠΙΔΟΡΠΙΑ
A21: U6315 | B21: VEGAN CHEESECAKE 16ΜΕΡΙΔΕΣ (1600GR) | C21: RASPBERRY VEGAN CHEESCAKE 16ΜΕΡΙΔΕΣ (1600GR) | D21: =VLOOKUP(F:F,Sheet1!A:B,2,FALSE) -> U3121 | F21: ΛΑΔΙ ΚΑΡΥΔΑΣ | H21: 90 | I21: ΕΠΙΔΟΡΠΙΑ | J21: 1000 | K21: 17.2 | L21: 17.2 | N21: ΛΑΔΙ ΚΑΡΥΔΑΣ | O21: 0.09 | P21: 1.55 | Q21: 1.55 | S21: ΕΠΙΔΟΡΠΙΑ
A22: U6315 | B22: VEGAN CHEESECAKE 16ΜΕΡΙΔΕΣ (1600GR) | C22: RASPBERRY VEGAN CHEESCAKE 16ΜΕΡΙΔΕΣ (1600GR) | D22: =VLOOKUP(F:F,Sheet1!A:B,2,FALSE) -> U3127 | F22: ΛΕΜΟΝΙ | H22: 60 | I22: ΕΠΙΔΟΡΠΙΑ | J22: 1000 | K22: 0.75 | L22: 0.75 | N22: ΛΕΜΟΝΙ | O22: 0.06 | P22: 0.05 | Q22: 0.05 | S22: ΕΠΙΔΟΡΠΙΑ
A23: U6315 | B23: VEGAN CHEESECAKE 16ΜΕΡΙΔΕΣ (1600GR) | C23: RASPBERRY VEGAN CHEESCAKE 16ΜΕΡΙΔΕΣ (1600GR) | D23: =VLOOKUP(F:F,Sheet1!A:B,2,FALSE) -> U3154 | F23: ΜΕΛΙ 900 | H23: 100 | I23: ΕΠΙΔΟΡΠΙΑ | J23: 1000 | K23: 4.82 | L23: 4.82 | N23: ΜΕΛΙ 900 | O23: 0.1 | P23: 0.48 | Q23: 0.48 | S23: ΕΠΙΔΟΡΠΙΑ
A24: U6315 | B24: VEGAN CHEESECAKE 16ΜΕΡΙΔΕΣ (1600GR) | C24: RASPBERRY VEGAN CHEESCAKE 16ΜΕΡΙΔΕΣ (1600GR) | D24: =VLOOKUP(F:F,Sheet1!A:B,2,FALSE) -> U3321 | F24: ΧΟΥΡΜΑΔΕΣ | H24: 250 | I24: ΕΠΙΔΟΡΠΙΑ | J24: 1000 | K24: 3.6 | L24: 3.6 | N24: ΧΟΥΡΜΑΔΕΣ | O24: 0.25 | P24: 0.9 | Q24: 0.9 | S24: ΕΠΙΔΟΡΠΙΑ
A25: U6311 | B25: ΑΡΝΑΚΙ ΓΙΟΥΒΕΤΣΙ | D25: =VLOOKUP(F:F,Sheet1!A:B,2,FALSE) -> U3014 | F25: ΑΛΑΤΙ | H25: 10 | I25: ΕΛΛΗΝΙΚΑ ΠΑΡΑΔΟΣΙΑΚΑ | J25: 1000 | K25: 0.89 | L25: 0.89 | N25: ΑΛΑΤΙ | O25: 0.01 | P25: 0.01 | Q25: 0.01 | S25: ΕΛΛΗΝΙΚΑ ΠΑΡΑΔΟΣΙΑΚΑ
A26: U6311 | B26: ΑΡΝΑΚΙ ΓΙΟΥΒΕΤΣΙ | D26: =VLOOKUP(F:F,Sheet1!A:B,2,FALSE) -> U3029 | F26: ΑΡΝΙ ΧΕΡΑΚΙ | H26: 2000 | I26: ΕΛΛΗΝΙΚΑ ΠΑΡΑΔΟΣΙΑΚΑ | J26: 1000 | K26: 8.98 | L26: 8.98 | N26: ΑΡΝΙ ΧΕΡΑΚΙ | O26: 2 | P26: 17.96 | Q26: 17.96 | S26: ΕΛΛΗΝΙΚΑ ΠΑΡΑΔΟΣΙΑΚΑ
A27: U6311 | B27: ΑΡΝΑΚΙ ΓΙΟΥΒΕΤΣΙ | D27: =VLOOKUP(F:F,Sheet1!A:B,2,FALSE) -> U3051 | F27: ΓΑΡΥΦΑΛΟ | H27: 10 | I27: ΕΛΛΗΝΙΚΑ ΠΑΡΑΔΟΣΙΑΚΑ | J27: 1000 | K27: 11.75 | L27: 11.75 | N27: ΓΑΡΥΦΑΛΟ | O27: 0.01 | P27: 0.12 | Q27: 0.12 | S27: ΕΛΛΗΝΙΚΑ ΠΑΡΑΔΟΣΙΑΚΑ
A28: U6311 | B28: ΑΡΝΑΚΙ ΓΙΟΥΒΕΤΣΙ | D28: =VLOOKUP(F:F,Sheet1!A:B,2,FALSE) -> U3072 | F28: ΖΑΧΑΡΗ | H28: 50 | I28: ΕΛΛΗΝΙΚΑ ΠΑΡΑΔΟΣΙΑΚΑ | J28: 1000 | K28: 0.91 | L28: 0.91 | N28: ΖΑΧΑΡΗ | O28: 0.05 | P28: 0.05 | Q28: 0.05 | S28: ΕΛΛΗΝΙΚΑ ΠΑΡΑΔΟΣΙΑΚΑ
A29: U6311 | B29: ΑΡΝΑΚΙ ΓΙΟΥΒΕΤΣΙ | D29: =VLOOKUP(F:F,Sheet1!A:B,2,FALSE) -> U3084 | F29: ΚΑΝΕΛΛΑ ΤΡΙΜΜΕΝΗ | H29: 5 | I29: ΕΛΛΗΝΙΚΑ ΠΑΡΑΔΟΣΙΑΚΑ | J29: 1000 | K29: 12.46 | L29: 12.46 | N29: ΚΑΝΕΛΛΑ ΤΡΙΜΜΕΝΗ | O29: 0.01 | P29: 0.06 | Q29: 0.06 | S29: ΕΛΛΗΝΙΚΑ ΠΑΡΑΔΟΣΙΑΚΑ
A30: U6311 | B30: ΑΡΝΑΚΙ ΓΙΟΥΒΕΤΣΙ | D30: =VLOOKUP(F:F,Sheet1!A:B,2,FALSE) -> U3114 | F30: ΚΡΕΜΜΥΔΙΑ ΞΕΡΑ | H30: 150 | I30: ΕΛΛΗΝΙΚΑ ΠΑΡΑΔΟΣΙΑΚΑ | J30: 1000 | K30: 0.6 | L30: 0.6 | N30: ΚΡΕΜΜΥΔΙΑ ΞΕΡΑ | O30: 0.15 | P30: 0.09 | Q30: 0.09 | S30: ΕΛΛΗΝΙΚΑ ΠΑΡΑΔΟΣΙΑΚΑ
A31: U6311 | B31: ΑΡΝΑΚΙ ΓΙΟΥΒΕΤΣΙ | D31: =VLOOKUP(F:F,Sheet1!A:B,2,FALSE) -> U3116 | F31: ΚΡΙΘΑΡΑΚΙ | H31: 1000 | I31: ΕΛΛΗΝΙΚΑ ΠΑΡΑΔΟΣΙΑΚΑ | J31: 1000 | K31: 1.15 | L31: 1.15 | N31: ΚΡΙΘΑΡΑΚΙ | O31: 1 | P31: 1.15 | Q31: 1.15 | S31: ΕΛΛΗΝΙΚΑ ΠΑΡΑΔΟΣΙΑΚΑ
A32: U6311 | B32: ΑΡΝΑΚΙ ΓΙΟΥΒΕΤΣΙ | D32: =VLOOKUP(F:F,Sheet1!A:B,2,FALSE) -> U3162 | F32: ΜΟΣΧΟΚΑΡΥΔΟ ΤΡΙΜ (0.5/ΤΜΧ) | H32: 10 | I32: ΕΛΛΗΝΙΚΑ ΠΑΡΑΔΟΣΙΑΚΑ | J32: 1000 | K32: 30.87 | L32: 30.87 | N32: ΜΟΣΧΟΚΑΡΥΔΟ ΤΡΙΜ (0.5/ΤΜΧ) | O32: 0.01 | P32: 0.31 | Q32: 0.31 | S32: ΕΛΛΗΝΙΚΑ ΠΑΡΑΔΟΣΙΑΚΑ
A33: U6311 | B33: ΑΡΝΑΚΙ ΓΙΟΥΒΕΤΣΙ | D33: =VLOOKUP(F:F,Sheet1!A:B,2,FALSE) -> U3169 | F33: ΜΠΑΧΑΡΙ | H33: 10 | I33: ΕΛΛΗΝΙΚΑ ΠΑΡΑΔΟΣΙΑΚΑ | J33: 1000 | K33: 14.05 | L33: 14.05 | N33: ΜΠΑΧΑΡΙ | O33: 0.01 | P33: 0.14 | Q33: 0.14 | S33: ΕΛΛΗΝΙΚΑ ΠΑΡΑΔΟΣΙΑΚΑ
A34: U6311 | B34: ΑΡΝΑΚΙ ΓΙΟΥΒΕΤΣΙ | D34: =VLOOKUP(F:F,Sheet1!A:B,2,FALSE) -> U3209 | F34: ΠΙΠΕΡΙ ΜΑΥΡΟ | H34: 10 | I34: ΕΛΛΗΝΙΚΑ ΠΑΡΑΔΟΣΙΑΚΑ | J34: 1000 | K34: 14.44 | L34: 14.44 | N34: ΠΙΠΕΡΙ ΜΑΥΡΟ | O34: 0.01 | P34: 0.14 | Q34: 0.14 | S34: ΕΛΛΗΝΙΚΑ ΠΑΡΑΔΟΣΙΑΚΑ
A35: U6311 | B35: ΑΡΝΑΚΙ ΓΙΟΥΒΕΤΣΙ | D35: =VLOOKUP(F:F,Sheet1!A:B,2,FALSE) -> U3221 | F35: ΠΟΛΤΟΣ ΤΟΜΑΤΑΣ | H35: 200 | I35: ΕΛΛΗΝΙΚΑ ΠΑΡΑΔΟΣΙΑΚΑ | J35: 1000 | K35: 3.01 | L35: 3.01 | N35: ΠΟΛΤΟΣ ΤΟΜΑΤΑΣ | O35: 0.2 | P35: 0.6 | Q35: 0.6 | S35: ΕΛΛΗΝΙΚΑ ΠΑΡΑΔΟΣΙΑΚΑ
A36: U6311 | B36: ΑΡΝΑΚΙ ΓΙΟΥΒΕΤΣΙ | D36: =VLOOKUP(F:F,Sheet1!A:B,2,FALSE) -> U3262 | F36: ΣΚΟΡΔΑ | H36: 50 | I36: ΕΛΛΗΝΙΚΑ ΠΑΡΑΔΟΣΙΑΚΑ | J36: 1000 | K36: 5.5 | L36: 5.5 | N36: ΣΚΟΡΔΑ | O36: 0.05 | P36: 0.28 | Q36: 0.28 | S36: ΕΛΛΗΝΙΚΑ ΠΑΡΑΔΟΣΙΑΚΑ
... A47: U6316 | B47: ΑΡΝΑΚΙ ΦΡΙΚΑΣΕ 2ΚΙΛΑ | D47: =VLOOKUP(F:F,Sheet1!A:B,2,FALSE) -> U3262 | F47: ΣΚΟΡΔΑ | H47: 5 | I47: ΕΛΛΗΝΙΚΑ ΠΑΡΑΔΟΣΙΑΚΑ | J47: 1000 | K47: 5.5 | L47: 5.5 | N47: ΣΚΟΡΔΑ | O47: 0.01 | P47: 0.03 | Q47: 0.03 | S47: ΕΛΛΗΝΙΚΑ ΠΑΡΑΔΟΣΙΑΚΑ
A48: U6129 | B48: ΑΡΝΙ ΚΟΤΣΙ | C48: ROAST LAMB | D48: =VLOOKUP(F:F,Sheet1!A:B,2,FALSE) -> U3014 | F48: ΑΛΑΤΙ | H48: ΧΩΡΙΣ ΠΟΣΟΤΗΤΑ | I48: ΕΛΛΗΝΙΚΑ ΠΑΡΑΔΟΣΙΑΚΑ | J48: 1000
A49: U6129 | B49: ΑΡΝΙ ΚΟΤΣΙ | C49: ROAST LAMB | D49: =VLOOKUP(F:F,Sheet1!A:B,2,FALSE) -> U3028 | F49: ΑΡΝΙ ΚΟΤΣΙ | H49: 200 | I49: ΕΛΛΗΝΙΚΑ ΠΑΡΑΔΟΣΙΑΚΑ | J49: 1000 | K49: 12.63 | L49: 12.63 | N49: ΑΡΝΙ ΚΟΤΣΙ | O49: 0.2 | P49: 2.53 | Q49: 2.53 | S49: ΕΛΛΗΝΙΚΑ ΠΑΡΑΔΟΣΙΑΚΑ
A50: U6129 | B50: ΑΡΝΙ ΚΟΤΣΙ | C50: ROAST LAMB | D50: =VLOOKUP(F:F,Sheet1!A:B,2,FALSE) -> U3127 | F50: ΛΕΜΟΝΙ | H50: 50 | I50: ΕΛΛΗΝΙΚΑ ΠΑΡΑΔΟΣΙΑΚΑ | J50: 1000
...

Sheet OIK104 MENU INGREDIENTS_semicol
A1: RECIPE CODE | B1: RECIPENAME | C1: NEW RECIPE NAME | D1: INGREDIENT CODE | E1: IME CODE | F1: INGREDIENT | G1: NEW INGREDIENT | H1: GRAMS / TMX | I1: CATEGORY | J1: KG / TMX | K1: Cost per Kg | L1: costcost | M1: OIK104 MENU | N1: Ingredient (from Ingredient Name) | O1: Kg per Recipe | P1: Cost per Recipe | Q1: costcosrecipe | R1: OIK104 MENU copy | S1: CATEGORY_ | T1: RESTAURANT (from OIK104 MENU) | U1: OIK512 MENU INGREDIENTS_ | V1: RESTAURANT (from OIK512 MENU_) (from OIK512 MENU INGREDIENTS_) | W1: Column1 | X1: Column2 | Y1: Column3 | Z1: Column4 | AA1: Column5 | AB1: ΣΧΟΛΙΑ
A2: U6153 | B2: 4 ΕΠΟΧΕΣ | D2: =VLOOKUP(F:F,Sheet1!A:B,2,FALSE) -> U3066 | F2: ΕΝΤΑΜ | H2: 90 | I2: ΠΙΤΣΑ | J2: 1000 | K2: 7.2 | L2: 7.2 | N2: ΕΝΤΑΜ | O2: 0.09 | P2: 0.65 | Q2: 0.65 | S2: ΠΙΤΣΑ | U2: 4 ΕΠΟΧΕΣ | V2: OIK512
A3: U6153 | B3: 4 ΕΠΟΧΕΣ | D3: =VLOOKUP(F:F,Sheet1!A:B,2,FALSE) -> U3075 | F3: ΖΥΜΗ ΠΙΤΣΑΣ 54 ΜΕΡΙΔΕΣ | H3: 1 | I3: ΠΙΤΣΑ | J3: 1 | L3: 0.45 | N3: ΖΥΜΗ ΠΙΤΣΑΣ 54 ΜΕΡΙΔΕΣ | O3: 1 | P3: 0 | Q3: 0.45 | S3: ΠΙΤΣΑ | U3: 4 ΕΠΟΧΕΣ | V3: OIK512
A4: U6153 | B4: 4 ΕΠΟΧΕΣ | D4: =VLOOKUP(F:F,Sheet1!A:B,2,FALSE) -> U3143 | F4: ΜΑΝΙΤΑΡΙΑ | H4: 40 | I4: ΠΙΤΣΑ | J4: 1000 | K4: 2.14 | L4: 2.14 | N4: ΜΑΝΙΤΑΡΙΑ | O4: 0.04 | P4: 0.09 | Q4: 0.09 | S4: ΠΙΤΣΑ | U4: 4 ΕΠΟΧΕΣ | V4: OIK512
A5: U6153 | B5: 4 ΕΠΟΧΕΣ | D5: =VLOOKUP(F:F,Sheet1!A:B,2,FALSE) -> U3164 | F5: ΜΟΤΣΑΡΕΛΑ | H5: 90 | I5: ΠΙΤΣΑ | J5: 1000 | K5: 6.74 | L5: 6.74 | N5: ΜΟΤΣΑΡΕΛΑ | O5: 0.09 | P5: 0.61 | Q5: 0.61 | S5: ΠΙΤΣΑ | U5: 4 ΕΠΟΧΕΣ | V5: OIK512
A6: U6153 | B6: 4 ΕΠΟΧΕΣ | D6: =VLOOKUP(F:F,Sheet1!A:B,2,FALSE) -> U3170 | F6: ΜΠΕΙΚΟΝ ΚΑΠΝΙΣΤΟ | H6: 40 | I6: ΠΙΤΣΑ | J6: 1000 | K6: 5.31 | L6: 5.31 | N6: ΜΠΕΙΚΟΝ ΚΑΠΝΙΣΤΟ | O6: 0.04 | P6: 0.21 | Q6: 0.21 | S6: ΠΙΤΣΑ | U6: 4 ΕΠΟΧΕΣ | V6: OIK512
A7: U6153 | B7: 4 ΕΠΟΧΕΣ | D7: =VLOOKUP(F:F,Sheet1!A:B,2,FALSE) -> U3207 | F7: ΠΕΠΕΡΟΝΙ | H7: 30 | I7: ΠΙΤΣΑ | J7: 1000 | K7: 4.18 | L7: 4.18 | N7: ΠΕΠΕΡΟΝΙ | O7: 0.03 | P7: 0.13 | Q7: 0.13 | S7: ΠΙΤΣΑ | U7: 4 ΕΠΟΧΕΣ | V7: OIK512
A8: U6153 | B8: 4 ΕΠΟΧΕΣ | D8: =VLOOKUP(F:F,Sheet1!A:B,2,FALSE) -> U3208 | F8: ΠΙΚ ΝΙΚ | H8: 40 | I8: ΠΙΤΣΑ | J8: 1000 | K8: 3.12 | L8: 3.12 | N8: ΠΙΚ ΝΙΚ | O8: 0.04 | P8: 0.12 | Q8: 0.12 | S8: ΠΙΤΣΑ | U8: 4 ΕΠΟΧΕΣ | V8: OIK512
A9: U6153 | B9: 4 ΕΠΟΧΕΣ | D9: =VLOOKUP(F:F,Sheet1!A:B,2,FALSE) -> U3252 | F9: ΣΑΛΤΣΑ ΠΙΤΣΑΣ | H9: 80 | I9: ΠΙΤΣΑ | J9: 1000 | L9: 11.7 | N9: ΣΑΛΤΣΑ ΠΙΤΣΑΣ | O9: 0.08 | P9: 0 | Q9: 0.94 | S9: ΠΙΤΣΑ | U9: 4 ΕΠΟΧΕΣ | V9: OIK512
A10: U6392 | B10: AFFOGATO | D10: =VLOOKUP(F:F,Sheet1!A:B,2,FALSE) -> #N/A | F10: RISTRETTO | H10: 24 | I10: ΕΠΙΔΟΡΠΙΑ | J10: 1000 | AB10: ΟΙΚ104
A11: U6392 | B11: AFFOGATO | D11: =VLOOKUP(F:F,Sheet1!A:B,2,FALSE) -> #N/A | F11: ΠΑΓΩΤΟ | H11: 100 | I11: ΕΠΙΔΟΡΠΙΑ | J11: 1000 | AB11: ΟΙΚ104
B12: BIANCO | D12: =VLOOKUP(F:F,Sheet1!A:B,2,FALSE) -> U3063 | F12: ΕΛΑΙΟΛΑΔΟ | H12: 70 | I12: ΕΛΛΗΝΙΚΑ ΠΑΡΑΔΟΣΙΑΚΑ | J12: 1000 | K12: 5.76 | L12: 5.76 | N12: ΕΛΑΙΟΛΑΔΟ | O12: 0.07 | P12: 0.4 | Q12: 0.4 | S12: ΕΛΛΗΝΙΚΑ ΠΑΡΑΔΟΣΙΑΚΑ
B13: BIANCO | D13: =VLOOKUP(F:F,Sheet1!A:B,2,FALSE) -> U3089 | F13: ΚΑΡΟΤΑ | H13: 80 | I13: ΕΛΛΗΝΙΚΑ ΠΑΡΑΔΟΣΙΑΚΑ | J13: 1000 | K13: 0.7 | L13: 0.7 | N13: ΚΑΡΟΤΑ | O13: 0.08 | P13: 0.06 | Q13: 0.06 | S13: ΕΛΛΗΝΙΚΑ ΠΑΡΑΔΟΣΙΑΚΑ
B14: BIANCO | D14: =VLOOKUP(F:F,Sheet1!A:B,2,FALSE) -> U3113 | F14: ΚΡΕΜΜΥΔΙ | H14: 80 | I14: ΕΛΛΗΝΙΚΑ ΠΑΡΑΔΟΣΙΑΚΑ | J14: 1000 | N14: ΚΡΕΜΜΥΔΙ | O14: 0.08 | P14: 0 | Q14: 0 | S14: ΕΛΛΗΝΙΚΑ ΠΑΡΑΔΟΣΙΑΚΑ
B15: BIANCO | D15: =VLOOKUP(F:F,Sheet1!A:B,2,FALSE) -> U3127 | F15: ΛΕΜΟΝΙ | H15: 50 | I15: ΕΛΛΗΝΙΚΑ ΠΑΡΑΔΟΣΙΑΚΑ | J15: 1000 | K15: 0.75 | L15: 0.75 | N15: ΛΕΜΟΝΙ | O15: 0.05 | P15: 0.04 | Q15: 0.04 | S15: ΕΛΛΗΝΙΚΑ ΠΑΡΑΔΟΣΙΑΚΑ
B16: BIANCO | D16: =VLOOKUP(F:F,Sheet1!A:B,2,FALSE) -> U3202 | F16: ΠΑΤΑΤΕΣ | H16: 100 | I16: ΕΛΛΗΝΙΚΑ ΠΑΡΑΔΟΣΙΑΚΑ | J16: 1000 | K16: 0.55 | L16: 0.55 | N16: ΠΑΤΑΤΕΣ | O16: 0.1 | P16: 0.06 | Q16: 0.06 | S16: ΕΛΛΗΝΙΚΑ ΠΑΡΑΔΟΣΙΑΚΑ
B17: BIANCO | D17: =VLOOKUP(F:F,Sheet1!A:B,2,FALSE) -> U3209 | F17: ΠΙΠΕΡΙ ΜΑΥΡΟ | H17: 10 | I17: ΕΛΛΗΝΙΚΑ ΠΑΡΑΔΟΣΙΑΚΑ | J17: 1000 | K17: 14.44 | L17: 14.44 | N17: ΠΙΠΕΡΙ ΜΑΥΡΟ | O17: 0.01 | P17: 0.14 | Q17: 0.14 | S17: ΕΛΛΗΝΙΚΑ ΠΑΡΑΔΟΣΙΑΚΑ
B18: BIANCO | D18: =VLOOKUP(F:F,Sheet1!A:B,2,FALSE) -> U3258 | F18: ΣΕΛΙΝΟ | H18: 80 | I18: ΕΛΛΗΝΙΚΑ ΠΑΡΑΔΟΣΙΑΚΑ | J18: 1000 | K18: 1.2 | L18: 1.2 | N18: ΣΕΛΙΝΟ | O18: 0.08 | P18: 0.1 | Q18: 0.1 | S18: ΕΛΛΗΝΙΚΑ ΠΑΡΑΔΟΣΙΑΚΑ
B19: BIANCO | D19: =VLOOKUP(F:F,Sheet1!A:B,2,FALSE) -> U3262 | F19: ΣΚΟΡΔΑ | H19: 50 | I19: ΕΛΛΗΝΙΚΑ ΠΑΡΑΔΟΣΙΑΚΑ | J19: 1000 | K19: 5.5 | L19: 5.5 | N19: ΣΚΟΡΔΑ | O19: 0.05 | P19: 0.28 | Q19: 0.28 | S19: ΕΛΛΗΝΙΚΑ ΠΑΡΑΔΟΣΙΑΚΑ
B20: DRESSING ΣΑΛΑΤΑ ΟΣΠΡΙΩΝ | D20: =VLOOKUP(F:F,Sheet1!A:B,2,FALSE) -> U3014 | F20: ΑΛΑΤΙ | H20: 10 | I20: ΕΝΔΙΑΜΕΣΑ | J20: 1000 | K20: 0.89 | L20: 0.89 | N20: ΑΛΑΤΙ | O20: 0.01 | P20: 0.01 | Q20: 0.01 | S20: ΕΝΔΙΑΜΕΣΑ
B21: DRESSING ΣΑΛΑΤΑ ΟΣΠΡΙΩΝ | D21: =VLOOKUP(F:F,Sheet1!A:B,2,FALSE) -> U3063 | F21: ΕΛΑΙΟΛΑΔΟ | H21: 50 | I21: ΕΝΔΙΑΜΕΣΑ | J21: 1000 | K21: 5.76 | L21: 5.76 | N21: ΕΛΑΙΟΛΑΔΟ | O21: 0.05 | P21: 0.29 | Q21: 0.29 | S21: ΕΝΔΙΑΜΕΣΑ
B22: DRESSING ΣΑΛΑΤΑ ΟΣΠΡΙΩΝ | D22: =VLOOKUP(F:F,Sheet1!A:B,2,FALSE) -> U3127 | F22: ΛΕΜΟΝΙ | H22: 50 | I22: ΕΝΔΙΑΜΕΣΑ | J22: 1000 | K22: 0.75 | L22: 0.75 | N22: ΛΕΜΟΝΙ | O22: 0.05 | P22: 0.04 | Q22: 0.04 | S22: ΕΝΔΙΑΜΕΣΑ
B23: DRESSING ΣΑΛΑΤΑ ΟΣΠΡΙΩΝ | D23: =VLOOKUP(F:F,Sheet1!A:B,2,FALSE) -> U3166 | F23: ΜΟΥΣΤΑΡΔΑ | H23: 40 | I23: ΕΝΔΙΑΜΕΣΑ | J23: 1000 | K23: 1.23 | L23: 1.23 | N23: ΜΟΥΣΤΑΡΔΑ | O23: 0.04 | P23: 0.05 | Q23: 0.05 | S23: ΕΝΔΙΑΜΕΣΑ
B24: DRESSING ΣΑΛΑΤΑ ΟΣΠΡΙΩΝ | D24: =VLOOKUP(F:F,Sheet1!A:B,2,FALSE) -> U3209 | F24: ΠΙΠΕΡΙ ΜΑΥΡΟ | H24: 10 | I24: ΕΝΔΙΑΜΕΣΑ | J24: 1000 | K24: 14.44 | L24: 14.44 | N24: ΠΙΠΕΡΙ ΜΑΥΡΟ | O24: 0.01 | P24: 0.14 | Q24: 0.14 | S24: ΕΝΔΙΑΜΕΣΑ
B25: DRESSING ΣΑΛΑΤΑ ΟΣΠΡΙΩΝ | D25: =VLOOKUP(F:F,Sheet1!A:B,2,FALSE) -> U3264 | F25: ΣΚΟΡΔΟ ΠΟΥΔΡΑ | H25: 40 | I25: ΕΝΔΙΑΜΕΣΑ | J25: 1000 | N25: ΣΚΟΡΔΟ ΠΟΥΔΡΑ | O25: 0.04 | P25: 0 | Q25: 0 | S25: ΕΝΔΙΑΜΕΣΑ
B26: DRESSING ΣΑΛΑΤΑ ΤΣΑΛΑΦΟΥΤΙ | D26: =VLOOKUP(F:F,Sheet1!A:B,2,FALSE) -> U3014 | F26: ΑΛΑΤΙ | H26: 10 | I26: ΕΝΔΙΑΜΕΣΑ | J26: 1000 | K26: 0.89 | L26: 0.89 | N26: ΑΛΑΤΙ | O26: 0.01 | P26: 0.01 | Q26: 0.01 | S26: ΕΝΔΙΑΜΕΣΑ
B27: DRESSING ΣΑΛΑΤΑ ΤΣΑΛΑΦΟΥΤΙ | D27: =VLOOKUP(F:F,Sheet1!A:B,2,FALSE) -> U3063 | F27: ΕΛΑΙΟΛΑΔΟ | H27: 100 | I27: ΕΝΔΙΑΜΕΣΑ | J27: 1000 | K27: 5.76 | L27: 5.76 | N27: ΕΛΑΙΟΛΑΔΟ | O27: 0.1 | P27: 0.58 | Q27: 0.58 | S27: ΕΝΔΙΑΜΕΣΑ
B28: DRESSING ΣΑΛΑΤΑ ΤΣΑΛΑΦΟΥΤΙ | D28: =VLOOKUP(F:F,Sheet1!A:B,2,FALSE) -> U3127 | F28: ΛΕΜΟΝΙ | H28: 50 | I28: ΕΝΔΙΑΜΕΣΑ | J28: 1000 | K28: 0.75 | L28: 0.75 | N28: ΛΕΜΟΝΙ | O28: 0.05 | P28: 0.04 | Q28: 0.04 | S28: ΕΝΔΙΑΜΕΣΑ
B29: DRESSING ΣΑΛΑΤΑ ΤΣΑΛΑΦΟΥΤΙ | D29: =VLOOKUP(F:F,Sheet1!A:B,2,FALSE) -> U3142 | F29: ΜΑΙΝΤΑΝΟΣ | H29: 50 | I29: ΕΝΔΙΑΜΕΣΑ | J29: 1000 | K29: 1.5 | L29: 1.5 | N29: ΜΑΙΝΤΑΝΟΣ | O29: 0.05 | P29: 0.08 | Q29: 0.08 | S29: ΕΝΔΙΑΜΕΣΑ
B30: DRESSING ΣΑΛΑΤΑ ΤΣΑΛΑΦΟΥΤΙ | D30: =VLOOKUP(F:F,Sheet1!A:B,2,FALSE) -> U3166 | F30: ΜΟΥΣΤΑΡΔΑ | H30: 69 | I30: ΕΝΔΙΑΜΕΣΑ | J30: 1000 | K30: 1.23 | L30: 1.23 | N30: ΜΟΥΣΤΑΡΔΑ | O30: 0.07 | P30: 0.08 | Q30: 0.08 | S30: ΕΝΔΙΑΜΕΣΑ
B31: DRESSING ΣΑΛΑΤΑ ΤΣΑΛΑΦΟΥΤΙ | D31: =VLOOKUP(F:F,Sheet1!A:B,2,FALSE) -> U3209 | F31: ΠΙΠΕΡΙ ΜΑΥΡΟ | H31: 10 | I31: ΕΝΔΙΑΜΕΣΑ | J31: 1000 | K31: 14.44 | L31: 14.44 | N31: ΠΙΠΕΡΙ ΜΑΥΡΟ | O31: 0.01 | P31: 0.14 | Q31: 0.14 | S31: ΕΝΔΙΑΜΕΣΑ
A32: U6298 | B32: MEDALLION | D32: =VLOOKUP(F:F,Sheet1!A:B,2,FALSE) -> U3008 | F32: MEDALLION | H32: 50 | I32: ΤΥΡΙΑ | J32: 1000 | K32: Η ΒΑΣΩ ΕΙΠΕ ΣΤΟ MEDALLION ΧΡΗΣΙΜΟΠΟΙΟΥΝ ΚΑΤΣΙΚΙΣΙΟ ΤΥΡΙ
A33: U6298 | B33: MEDALLION | D33: =VLOOKUP(F:F,Sheet1!A:B,2,FALSE) -> #N/A | F33: ΚΑΤΣΙΚΙΣΙΟ ΤΥΡΙ | H33: 50 | I33: ΤΥΡΙΑ | J33: 1000 | K33: 17.5 | L33: 17.5 | N33: MEDALLION | O33: 0.05 | P33: 0.88 | Q33: 0.88 | S33: ΤΥΡΙΑ | AB33: Η ΒΑΣΩ ΕΙΠΕ ΣΤΟ MEDALLION ΧΡΗΣΙΜΟΠΟΙΟΥΝ ΚΑΤΣΙΚΙΣΙΟ ΤΥΡΙ
A34: U6294 | B34: REZZANO | C34: REZZANA TOSSIZZA | D34: =VLOOKUP(F:F,Sheet1!A:B,2,FALSE) -> U3010 | F34: REZZANO | H34: 50 | I34: ΤΥΡΙΑ | J34: 1000 | K34: 20.19 | L34: 20.19 | N34: REZZANO | O34: 0.05 | P34: 1.01 | Q34: 1.01 | S34: ΤΥΡΙΑ
A35: U6296 | B35: TΣΑΛΑΦΟΥΤΙ | C35: TSALAFOUTI | D35: =VLOOKUP(F:F,Sheet1!A:B,2,FALSE) -> U3291 | F35: ΤΣΑΛΑΦΟΥΤΙ | H35: 50 | I35: ΤΥΡΙΑ | J35: 1000 | K35: 5.5 | L35: 5.5 | N35: ΤΣΑΛΑΦΟΥΤΙ | O35: 0.05 | P35: 0.28 | Q35: 0.28 | S35: ΤΥΡΙΑ
A36: U6315 | B36: VEGAN CHEESECAKE 16ΜΕΡΙΔΕΣ (1600GR) | C36: RASPBERRY VEGAN CHEESCAKE 16ΜΕΡΙΔΕΣ (1600GR) | D36: =VLOOKUP(F:F,Sheet1!A:B,2,FALSE) -> U3004 | F36: CHIA ΣΠΟΡΟΙ | H36: 50 | I36: ΕΠΙΔΟΡΠΙΑ | J36: 1000 | K36: 3.89 | L36: 3.89 | N36: CHIA ΣΠΟΡΟΙ | O36: 0.05 | P36: 0.19 | Q36: 0.19 | S36: ΕΠΙΔΟΡΠΙΑ
A37: U6315 | B37: VEGAN CHEESECAKE 16ΜΕΡΙΔΕΣ (1600GR) | C37: RASPBERRY VEGAN CHEESCAKE 16ΜΕΡΙΔΕΣ (1600GR) | D37: =VLOOKUP(F:F,Sheet1!A:B,2,FALSE) -> U3022 | F37: ΑΜΥΓΔΑΛΟΨΥΧΑ 1kg | H37: 200 | I37: ΕΠΙΔΟΡΠΙΑ | J37: 1000 | K37: 8.75 | L37: 8.75 | N37: ΑΜΥΓΔΑΛΟΨΥΧΑ 1kg | O37: 0.2 | P37: 1.75 | Q37: 1.75 | S37: ΕΠΙΔΟΡΠΙΑ
A38: U6315 | B38: VEGAN CHEESECAKE 16ΜΕΡΙΔΕΣ (1600GR) | C38: RASPBERRY VEGAN CHEESCAKE 16ΜΕΡΙΔΕΣ (1600GR) | D38: =VLOOKUP(F:F,Sheet1!A:B,2,FALSE) -> U3034 | F38: ΒΑΝΙΛΙΑ | H38: 1 | I38: ΕΠΙΔΟΡΠΙΑ | J38: 1000 | K38: 34.07 | L38: 34.07 | N38: ΒΑΝΙΛΙΑ | O38: 0 | P38: 0.03 | Q38: 0.03 | S38: ΕΠΙΔΟΡΠΙΑ
A39: U6315 | B39: VEGAN CHEESECAKE 16ΜΕΡΙΔΕΣ (1600GR) | C39: RASPBERRY VEGAN CHEESCAKE 16ΜΕΡΙΔΕΣ (1600GR) | D39: =VLOOKUP(F:F,Sheet1!A:B,2,FALSE) -> U3036 | F39: ΒΑΤΟΜΟΥΡΟ ΚΟΚΚΙΝΟ | H39: 200 | I39: ΕΠΙΔΟΡΠΙΑ | J39: 1000 | K39: 4.65 | L39: 4.65 | N39: ΒΑΤΟΜΟΥΡΟ ΚΟΚΚΙΝΟ | O39: 0.2 | P39: 0.93 | Q39: 0.93 | S39: ΕΠΙΔΟΡΠΙΑ
A40: U6315 | B40: VEGAN CHEESECAKE 16ΜΕΡΙΔΕΣ (1600GR) | C40: RASPBERRY VEGAN CHEESCAKE 16ΜΕΡΙΔΕΣ (1600GR) | D40: =VLOOKUP(F:F,Sheet1!A:B,2,FALSE) -> U3047 | F40: ΓΑΛΑ ΚΑΡΥΔΑΣ | H40: 180 | I40: ΕΠΙΔΟΡΠΙΑ | J40: 1000 | K40: 2.08 | L40: 2.08 | N40: ΓΑΛΑ ΚΑΡΥΔΑΣ | O40: 0.18 | P40: 0.37 | Q40: 0.37 | S40: ΕΠΙΔΟΡΠΙΑ
...

Sheet Sheet1
A1: ΒΑΣΙΛΙΚΟΣ | B1: U3001
A2: ΚΕΦΑΛΟΓΡΑΒΙΕΡΑ | B2: U3002
A3: ΞΙΝΟ ΝΕΡΟ 250 | B3: U3003
A4: CHIA ΣΠΟΡΟΙ | B4: U3004
A5: DRESSING ΣΑΛΑΤΑ ΟΣΠΡΙΩΝ | B5: U3005
A6: DRESSING ΣΑΛΑΤΑ ΤΣΑΛΑΦΟΥΤΙ | B6: U3006
A7: GOJIBERRIES ΑΠΟΞΗΡΑΜΕΝΑ | B7: U3007
A8: MEDALLION | B8: U3008
A9: MEDALLION ΚΑΤΣ.ΜΑΛ.ΤΥΡΙ ΠΑΠΡΙΚΑ-ΒΑΣ 100γρ | B9: U3009
A10: REZZANO | B10: U3010
A11: VINEGRET ΒΑΛΣΑΜΙΚΟ | B11: U3011
A12: WORCESTER | B12: U3012
... A331: ΨΩΜΙ ΧΩΡΙΑΤΙΚΟ | B331: U3331
